<?xml version="1.0"?>
<xacro:macro xmlns:xacro="http://www.ros.org/wiki/xacro" name="robot_urdf">
  <xacro:property name="mesh_path" value="file://$(find robot_description)/meshes" />

  <link name="base_link">
    <inertial>
      <origin rpy="0 0 0" xyz="0.00252285 -0.00063439 0.03023409" />
      <mass value="4.3041648" />
      <inertia ixx="0.02680559" ixy="-5.49e-06" ixz="5.389e-05" iyy="0.01083128" iyz="-0.00011229"
        izz="0.02180955" />
    </inertial>
    <visual>
      <origin rpy="0 0 0" xyz="0 0 0" />
      <geometry>
        <mesh filename="${mesh_path}/base_link_simple.STL" />
      </geometry>
      <material name="">
        <color rgba="0.8 0.4 0 1" />
      </material>
    </visual>
    <collision>
      <origin rpy="0 0 0" xyz="0 0 0.18" />
      <geometry>
        <!-- <mesh filename="${mesh_path}/base_link_simple.STL" /> -->
        <box size="0.15 0.25 0.35" />
      </geometry>
    </collision>
  </link>

  <!-- ~~~~~~~~~~~~~~~~~ lumber ~~~~~~~~~~~~~~~~~~~~~~~~~~~~~~~~ -->
  <link name="lumber_yaw">
    <inertial>
      <origin rpy="0 0 0" xyz="-0.01800066 1.4e-06 0.02432982" />
      <mass value="0.36251906" />
      <inertia ixx="0.00035849" ixy="0" ixz="6.896e-05" iyy="0.00045823" iyz="-1e-08"
        izz="0.00063906" />
    </inertial>
    <visual>
      <origin rpy="0 0 0" xyz="0 0 0" />
      <geometry>
        <mesh filename="${mesh_path}/lumber_yaw.STL" />
      </geometry>
      <material name="">
        <color rgba="1 0.4 0.4 1" />
      </material>
    </visual>
  </link>
  <joint name="lumber_yaw_joint" type="fixed">
    <origin rpy="0 0 -4.54911392613975E-05" xyz="0.00244999999994827 0 0.115534033809005" />
    <parent link="base_link" />
    <child link="lumber_yaw" />
    <axis xyz="0 0 1" />
    <limit effort="1000" lower="-3.14" upper="3.14" velocity="100" />
  </joint>
  <link name="lumber_roll">
    <inertial>
      <origin rpy="0 0 0" xyz="-0.00029919 0.0003642 -0.00019197" />
      <mass value="0.03412073" />
      <inertia ixx="4.93e-06" ixy="1.3e-07" ixz="0" iyy="5.42e-06" iyz="-9e-08" izz="4.83e-06" />
    </inertial>
    <visual>
      <origin rpy="0 0 0" xyz="0 0 0" />
      <geometry>
        <mesh filename="${mesh_path}/lumber_roll.STL" />
      </geometry>
      <material name="">
        <color rgba="1 1 1 1" />
      </material>
    </visual>

  </link>
  <joint name="lumber_roll_joint" type="fixed">
    <origin rpy="1.57079632679491 0 -1.5707963267949" xyz="0 0 0.0405" />
    <parent link="lumber_yaw" />
    <child link="lumber_roll" />
    <axis xyz="0 0 1" />
    <limit effort="1000" lower="-3.14" upper="3.14" velocity="100" />
  </joint>
  <link name="lumber_pitch">
    <inertial>
      <origin rpy="0 0 0" xyz="0.00070244 0.21072612 -0.00117164" />
      <mass value="8.8571074" />
      <inertia ixx="0.14777412" ixy="-0.00392755" ixz="0.00035997" iyy="0.06085873"
        iyz="-0.00078171"
        izz="0.11164753" />
    </inertial>
    <visual>
      <origin rpy="0 0 0" xyz="0 0 0" />
      <geometry>
        <mesh filename="${mesh_path}/lumber_pitch.STL" />
      </geometry>
      <material name="">
        <color rgba="1 1 1 1" />
      </material>
    </visual>

  </link>
  <joint name="lumber_pitch_joint" type="fixed">
    <origin rpy="0 1.5707963267949 0" xyz="0 0 0" />
    <parent link="lumber_roll" />
    <child link="lumber_pitch" />
    <axis xyz="0 0 -1" />
    <limit effort="1000" lower="-3.14" upper="3.14" velocity="100" />
  </joint>

  <link name="waist_motor_a_link">
    <inertial>
      <origin rpy="0 0 0" xyz="-0.04046842 0 -0.00673515" />
      <mass value="0.05818703" />
      <inertia ixx="1.004e-05" ixy="-3e-08" ixz="-1.16e-05" iyy="5.053e-05" iyz="0" izz="4.77e-05" />
    </inertial>
    <visual>
      <origin rpy="0 0 0" xyz="0 0 0" />
      <geometry>
        <mesh filename="${mesh_path}/waist_motor_a_link.STL" />
      </geometry>
      <material name="">
        <color rgba="0.776470588235294 0.756862745098039 0.737254901960784 1" />
      </material>
    </visual>

  </link>
  <joint name="waist_motor_a_link_joint" type="fixed">
    <origin rpy="0 0 0" xyz="0 0.0749999999999926 0.0708000000001417" />
    <parent link="lumber_pitch" />
    <child link="waist_motor_a_link" />
    <axis xyz="0 0 1" />
    <limit effort="1000" lower="-3.14" upper="3.14" velocity="100" />
  </joint>
  <link name="waist_motor_a_ball">
    <inertial>
      <origin rpy="0 0 0" xyz="-0.00179727 0.03749978 -3.559e-05" />
      <mass value="0.03613902" />
      <inertia ixx="3.412e-05" ixy="0" ixz="0" iyy="2.43e-06" iyz="0" izz="3.624e-05" />
    </inertial>
    <visual>
      <origin rpy="0 0 0" xyz="0 0 0" />
      <geometry>
        <mesh filename="${mesh_path}/waist_motor_a_ball.STL" />
      </geometry>
      <material name="">
        <color rgba="0.776470588235294 0.756862745098039 0.737254901960784 1" />
      </material>
    </visual>

  </link>
  <joint name="waist_motor_a_ball_joint" type="fixed">
    <origin rpy="3.14159265358979 0 0" xyz="-0.065 0 -0.0108000000001461" />
    <parent link="waist_motor_a_link" />
    <child link="waist_motor_a_ball" />
    <axis xyz="0 0 0" />
  </joint>
  <link name="waist_motor_a_loop">
    <inertial>
      <origin rpy="0 0 0" xyz="0 0 0.00052471" />
      <mass value="0.01765296" />
      <inertia ixx="8e-07" ixy="0" ixz="0" iyy="8e-07" iyz="0" izz="3.5e-07" />
    </inertial>
    <visual>
      <origin rpy="0 0 0" xyz="0 0 0" />
      <geometry>
        <mesh filename="${mesh_path}/waist_motor_a_loop.STL" />
      </geometry>
      <material name="">
        <color rgba="1 1 1 1" />
      </material>
    </visual>

  </link>
  <joint name="waist_motor_a_loop_joint" type="fixed">
    <origin rpy="3.14159265358979 0 0" xyz="0 0.0749999999999924 0" />
    <parent link="waist_motor_a_ball" />
    <child link="waist_motor_a_loop" />
    <axis xyz="0 0 0" />
  </joint>
  <link name="waist_motor_b_link">
    <inertial>
      <origin rpy="0 0 0" xyz="-0.04046842 0 -0.00673515" />
      <mass value="0.05818703" />
      <inertia ixx="1.004e-05" ixy="-3e-08" ixz="-1.16e-05" iyy="5.053e-05" iyz="0" izz="4.77e-05" />
    </inertial>
    <visual>
      <origin rpy="0 0 0" xyz="0 0 0" />
      <geometry>
        <mesh filename="${mesh_path}/waist_motor_b_link.STL" />
      </geometry>
      <material name="">
        <color rgba="0.776470588235294 0.756862745098039 0.737254901960784 1" />
      </material>
    </visual>

  </link>
  <joint name="waist_motor_b_link_joint" type="fixed">
    <origin rpy="3.14159265358979 0 0" xyz="0 0.0750000000000303 -0.0708000000000074" />
    <parent link="lumber_pitch" />
    <child link="waist_motor_b_link" />
    <axis xyz="0 0 1" />
    <limit effort="1000" lower="-3.14" upper="3.14" velocity="100" />
  </joint>
  <link name="waist_motor_b_ball">
    <inertial>
      <origin rpy="0 0 0" xyz="3.559e-05 -0.03749978 0.00179727" />
      <mass value="0.03613902" />
      <inertia ixx="3.624e-05" ixy="0" ixz="0" iyy="2.43e-06" iyz="0" izz="3.412e-05" />
    </inertial>
    <visual>
      <origin rpy="0 0 0" xyz="0 0 0" />
      <geometry>
        <mesh filename="${mesh_path}/waist_motor_b_ball.STL" />
      </geometry>
      <material name="">
        <color rgba="1 1 1 1" />
      </material>
    </visual>

  </link>
  <joint name="waist_motor_b_ball_joint" type="fixed">
    <origin rpy="3.14159265358979 1.5707963267949 0" xyz="-0.0650000000000492 0 -0.0108000000000005" />
    <parent link="waist_motor_b_link" />
    <child link="waist_motor_b_ball" />
    <axis xyz="0 0 0" />
  </joint>
  <link name="waist_motor_b_loop">
    <inertial>
      <origin rpy="0 0 0" xyz="-0.00052471 0 0" />
      <mass value="0.01765296" />
      <inertia ixx="3.5e-07" ixy="0" ixz="0" iyy="8e-07" iyz="0" izz="8e-07" />
    </inertial>
    <visual>
      <origin rpy="0 0 0" xyz="0 0 0" />
      <geometry>
        <mesh filename="${mesh_path}/waist_motor_b_loop.STL" />
      </geometry>
      <material name="">
        <color rgba="1 1 1 1" />
      </material>
    </visual>

  </link>
  <joint name="waist_motor_b_loop_joint" type="fixed">
    <origin rpy="0 0 0" xyz="0 -0.0749999999999924 0" />
    <parent link="waist_motor_b_ball" />
    <child link="waist_motor_b_loop" />
    <axis xyz="0 0 0" />
  </joint>
  <!-- ~~~~~~~~~~~~~~~~~ lumber ~~~~~~~~~~~~~~~~~~~~~~~~~~~~~~~~ -->

  <!-- ~~~~~~~~~~~~~~~~~ left arm ~~~~~~~~~~~~~~~~~~~~~~~~~~~~~~~~ -->
  <link name="left_shoulder_pitch">
    <inertial>
      <origin rpy="0 0 0" xyz="-0.00251212 -0.00149141 -0.05674475" />
      <mass value="1.0067875" />
      <inertia ixx="0.00108106" ixy="2.069e-05" ixz="1.583e-05" iyy="0.00096162" iyz="1.04e-06"
        izz="0.0008545" />
    </inertial>
    <visual>
      <origin rpy="0 0 0" xyz="0 0 0" />
      <geometry>
        <mesh filename="${mesh_path}/left_shoulder_pitch.STL" />
      </geometry>
      <material name="">
        <color rgba="1 1 1 1" />
      </material>
    </visual>

  </link>
  <joint name="left_shoulder_pitch_joint" type="fixed">
    <origin rpy="0 0 -3.14159265358978" xyz="0 0.255999999999995 -0.145800000000004" />
    <parent link="lumber_pitch" />
    <child link="left_shoulder_pitch" />
    <axis xyz="0 0 -1" />
    <limit effort="1000" lower="-3.14" upper="3.14" velocity="100" />
  </joint>
  <link name="left_shoulder_roll">
    <inertial>
      <origin rpy="0 0 0" xyz="0.000154 0.07784637 -0.02711338" />
      <mass value="0.69169508" />
      <inertia ixx="0.00133669" ixy="1.21e-06" ixz="3.26e-06" iyy="0.00065344" iyz="9.451e-05"
        izz="0.00117974" />
    </inertial>
    <visual>
      <origin rpy="0 0 0" xyz="0 0 0" />
      <geometry>
        <mesh filename="${mesh_path}/left_shoulder_roll.STL" />
      </geometry>
      <material name="">
        <color rgba="1 1 1 1" />
      </material>
    </visual>

  </link>
  <joint name="left_shoulder_roll_joint" type="fixed">
    <origin rpy="0 -1.5708 0" xyz="-0.0313 0 -0.0592" />
    <parent link="left_shoulder_pitch" />
    <child link="left_shoulder_roll" />
    <axis xyz="0 0 -1" />
    <limit effort="1000" lower="-3.14" upper="3.14" velocity="100" />
  </joint>
  <link name="left_shoulder_yaw">
    <inertial>
      <origin rpy="0 0 0" xyz="-2.68e-06 0.00182113 -0.00392718" />
      <mass value="0.72559372" />
      <inertia ixx="0.00116043" ixy="-5.8e-07" ixz="1.27e-06" iyy="0.00117758" iyz="-6.33e-05"
        izz="0.00048696" />
    </inertial>
    <visual>
      <origin rpy="0 0 0" xyz="0 0 0" />
      <geometry>
        <mesh filename="${mesh_path}/left_shoulder_yaw.STL" />
      </geometry>
      <material name="">
        <color rgba="1 1 1 1" />
      </material>
    </visual>

  </link>
  <joint name="left_shoulder_yaw_joint" type="fixed">
    <origin rpy="1.57079632679488 1.5707963267949 0" xyz="0 0.1252 -0.0313000000000029" />
    <parent link="left_shoulder_roll" />
    <child link="left_shoulder_yaw" />
    <axis xyz="0 0 1" />
    <limit effort="1000" lower="-3.14" upper="3.14" velocity="100" />
  </joint>
  <link name="left_elbow_pitch">
    <inertial>
      <origin rpy="0 0 0" xyz="2.604e-05 0.07528242 0.0268658" />
      <mass value="0.69780135" />
      <inertia ixx="0.00116267" ixy="2.7e-07" ixz="1.6e-07" iyy="0.00064619" iyz="-0.00010622"
        izz="0.00096882" />
    </inertial>
    <visual>
      <origin rpy="0 0 0" xyz="0 0 0" />
      <geometry>
        <mesh filename="${mesh_path}/left_elbow_pitch.STL" />
      </geometry>
      <material name="">
        <color rgba="1 1 1 1" />
      </material>
    </visual>

  </link>
  <joint name="left_elbow_pitch_joint" type="fixed">
    <origin rpy="-1.5707963267949 0 0" xyz="0 -0.031 -0.0365000000000021" />
    <parent link="left_shoulder_yaw" />
    <child link="left_elbow_pitch" />
    <axis xyz="0 0 1" />
    <limit effort="1000" lower="-3.14" upper="3.14" velocity="100" />
  </joint>
  <link name="left_elbow_yaw">
    <inertial>
      <origin rpy="0 0 0" xyz="3.656e-5 0.00424199 -0.05421422" />
      <mass value="0.28787886" />
      <inertia ixx="0.00071486" ixy="9e-08" ixz="-3.7e-07" iyy="0.00069793" iyz="2.677e-05"
        izz="0.00054487" />
    </inertial>
    <visual>
      <origin rpy="0 0 0" xyz="0 0 0" />
      <geometry>
        <mesh filename="${mesh_path}/left_elbow_yaw2.STL" />
      </geometry>
      <material name="">
        <color rgba="1 1 1 1" />
      </material>
    </visual>

  </link>
  <joint name="left_elbow_yaw_joint" type="fixed">
    <origin rpy="1.5707963267949  -1.5708 0" xyz="0 0.116999999999998 0.0310000000000001" />
    <parent link="left_elbow_pitch" />
    <child link="left_elbow_yaw" />
    <axis xyz="0 0 1" />
    <limit effort="1000" lower="-3.14" upper="3.14" velocity="100" />
  </joint>
  <link name="left_wrist_pitch">
    <inertial>
      <origin rpy="0 0 0" xyz="-9.994e-05 0 0.00229425" />
      <mass value="0.00900738" />
      <inertia ixx="2.4e-07" ixy="0" ixz="0" iyy="5.7e-07" iyz="0" izz="3.8e-07" />
    </inertial>
    <visual>
      <origin rpy="0 0 0" xyz="0 0 0" />
      <geometry>
        <mesh filename="${mesh_path}/left_wrist_pitch.STL" />
      </geometry>
      <material name="">
        <color rgba="1 1 1 1" />
      </material>
    </visual>

  </link>
  <joint name="left_wrist_pitch_joint" type="fixed">
    <origin rpy="1.5708 0 0" xyz="0.006 9.9998E-05 -0.1394" />
    <parent link="left_elbow_yaw" />
    <child link="left_wrist_pitch" />
    <axis xyz="-1 0 0" />
    <limit effort="1000" lower="-3.14" upper="3.14" velocity="100" />
  </joint>
  <link name="left_wrist_roll">
    <inertial>
      <origin rpy="0 0 0" xyz="-0.02171427 -0.02820011 6.794e-05" />
      <mass value="0.35281837" />
      <inertia ixx="0.00020094" ixy="-2.81e-05" ixz="0" iyy="0.00016807" iyz="1e-08"
        izz="0.00022252" />
    </inertial>
    <visual>
      <origin rpy="0 0 0" xyz="0 0 0" />
      <geometry>
        <mesh filename="${mesh_path}/left_wrist_roll.STL" />
      </geometry>
      <material name="">
        <color rgba="0.89804 0.91765 0.92941 1" />
      </material>
    </visual>

  </link>
  <joint name="left_wrist_roll_joint" type="fixed">
    <origin rpy="-0.65869 1.5708 -0.65869" xyz="0 0 0" />
    <parent link="left_wrist_pitch" />
    <child link="left_wrist_roll" />
    <axis xyz="1 0 0" />
    <limit effort="1000" lower="-3.14" upper="3.14" velocity="100" />
  </joint>
  <!-- ~~~~~~~~~~~~~~~~~ left arm ~~~~~~~~~~~~~~~~~~~~~~~~~~~~~~~~ -->

  <!-- ~~~~~~~~~~~~~~~~~ right arm ~~~~~~~~~~~~~~~~~~~~~~~~~~~~~~~~ -->
  <link name="right_shoulder_pitch">
    <inertial>
      <origin rpy="0 0 0" xyz="0.00250704 -0.00149173 -0.05674328" />
      <mass value="1.0067875" />
      <inertia ixx="0.00108106" ixy="-2.069e-05" ixz="-1.583e-05" iyy="0.00096162" iyz="8.4e-07"
        izz="0.0008545" />
    </inertial>
    <visual>
      <origin rpy="0 0 0" xyz="0 0 0" />
      <geometry>
        <mesh filename="${mesh_path}/right_shoulder_pitch.STL" />
      </geometry>
      <material name="">
        <color rgba="1 1 1 1" />
      </material>
    </visual>

  </link>
  <joint name="right_shoulder_pitch_joint" type="fixed">
    <origin rpy="3.1416 0 0" xyz="0 0.256 0.1458" />
    <parent link="lumber_pitch" />
    <child link="right_shoulder_pitch" />
    <axis xyz="0 0 1" />
    <limit effort="1000" lower="-3.14" upper="3.14" velocity="100" />
  </joint>
  <link name="right_shoulder_roll">
    <inertial>
      <origin rpy="0 0 0" xyz="9.998e-05 -0.07787239 -0.02705625" />
      <mass value="0.69142604" />
      <inertia ixx="0.00133757" ixy="-3.8e-07" ixz="-2.53e-06" iyy="0.00065281" iyz="-9.481e-05"
        izz="0.00118057" />
    </inertial>
    <visual>
      <origin rpy="0 0 0" xyz="0 0 0" />
      <geometry>
        <mesh filename="${mesh_path}/right_shoulder_roll.STL" />
      </geometry>
      <material name="">
        <color rgba="1 1 1 1" />
      </material>
    </visual>

  </link>
  <joint name="right_shoulder_roll_joint" type="fixed">
    <origin rpy="3.1416 -1.5708 0" xyz="0.0313 0 -0.0592" />
    <parent link="right_shoulder_pitch" />
    <child link="right_shoulder_roll" />
    <axis xyz="0 0 1" />
    <limit effort="1000" lower="-3.14" upper="3.14" velocity="100" />
  </joint>
  <link name="right_shoulder_yaw">
    <inertial>
      <origin rpy="0 0 0" xyz="-0.00189082 -0.00017102 0.03175107" />
      <mass value="0.604503" />
      <inertia ixx="0.00050135" ixy="2.4e-06" ixz="6.05e-06" iyy="0.00055045" iyz="-1.7e-07"
        izz="0.00049583" />
    </inertial>
    <visual>
      <origin rpy="0 0 0" xyz="0 0 0" />
      <geometry>
        <mesh filename="${mesh_path}/right_shoulder_yaw.STL" />
      </geometry>
      <material name="">
        <color rgba="1 1 1 1" />
      </material>
    </visual>

  </link>
  <joint name="right_shoulder_yaw_joint" type="fixed">
    <origin rpy="1.5708 0 0" xyz="0 -0.1252 -0.0313" />
    <parent link="right_shoulder_roll" />
    <child link="right_shoulder_yaw" />
    <axis xyz="0 0 1" />
    <limit effort="1000" lower="-3.14" upper="3.14" velocity="100" />
  </joint>
  <link name="right_elbow_pitch">
    <inertial>
      <origin rpy="0 0 0" xyz="-2.604e-05 -0.07529828 0.02685625" />
      <mass value="0.69780135" />
      <inertia ixx="0.00116302" ixy="2.7e-07" ixz="-1.6e-07" iyy="0.00064594" iyz="0.00010623"
        izz="0.00096939" />
    </inertial>
    <visual>
      <origin rpy="0 0 0" xyz="0 0 0" />
      <geometry>
        <mesh filename="${mesh_path}/right_elbow_pitch.STL" />
      </geometry>
      <material name="">
        <color rgba="1 1 1 1" />
      </material>
    </visual>

  </link>
  <joint name="right_elbow_pitch_joint" type="fixed">
    <origin rpy="-1.5707963267949 0 -1.5707963267949" xyz="-0.0309999999999999 0 0.0365000000000022" />
    <parent link="right_shoulder_yaw" />
    <child link="right_elbow_pitch" />
    <axis xyz="0 0 -1" />
    <limit effort="1000" lower="-3.14" upper="3.14" velocity="100" />
  </joint>
  <link name="right_elbow_yaw">
    <inertial>
      <origin rpy="0 0 0" xyz="-3.65e-5 -0.00422926 -0.05414537" />
      <mass value="0.28835476" />
      <inertia ixx="0.00071572" ixy="9e-08" ixz="3.7e-07" iyy="0.00069879" iyz="-2.692e-05"
        izz="0.00054493" />
    </inertial>
    <visual>
      <origin rpy="0 0 0" xyz="0 0 0" />
      <geometry>
        <mesh filename="${mesh_path}/right_elbow_yaw2.STL" />
      </geometry>
      <material name="">
        <color rgba="1 1 1 1" />
      </material>
    </visual>

  </link>
  <joint name="right_elbow_yaw_joint" type="fixed">
    <origin rpy="-1.5707963267949 -1.5708 0" xyz="0 -0.116999999999998 0.0310000000000001" />
    <parent link="right_elbow_pitch" />
    <child link="right_elbow_yaw" />
    <axis xyz="0 0 -1" />
    <limit effort="1000" lower="-3.14" upper="3.14" velocity="100" />
  </joint>
  <link name="right_wrist_pitch">
    <inertial>
      <origin rpy="0 0 0" xyz="-9.994e-05 0 0.00229425" />
      <mass value="0.00900738" />
      <inertia ixx="2.4e-07" ixy="0" ixz="0" iyy="5.7e-07" iyz="0" izz="3.8e-07" />
    </inertial>
    <visual>
      <origin rpy="0 0 0" xyz="0 0 0" />
      <geometry>
        <mesh filename="${mesh_path}/right_wrist_pitch.STL" />
      </geometry>
      <material name="">
        <color rgba="1 1 1 1" />
      </material>
    </visual>

  </link>
  <joint name="right_wrist_pitch_joint" type="fixed">
    <origin rpy="1.5708 0 0" xyz="0.006 9.9998E-05 -0.1394" />
    <parent link="right_elbow_yaw" />
    <child link="right_wrist_pitch" />
    <axis xyz="1 0 0" />
    <limit effort="1000" lower="-3.14" upper="3.14" velocity="100" />
  </joint>
  <link name="right_wrist_roll">
    <inertial>
      <origin rpy="0 0 0" xyz="-0.02171427 -0.02820011 6.794e-05" />
      <mass value="0.35281837" />
      <inertia ixx="0.00020094" ixy="-2.81e-05" ixz="0" iyy="0.00016807" iyz="1e-08"
        izz="0.00022252" />
    </inertial>
    <visual>
      <origin rpy="0 0 0" xyz="0 0 0" />
      <geometry>
        <mesh filename="${mesh_path}/right_wrist_roll.STL" />
      </geometry>
      <material name="">
        <color rgba="1 1 1 1" />
      </material>
    </visual>

  </link>
  <joint name="right_wrist_roll_joint" type="fixed">
    <origin rpy="-0.65869 1.5708 -0.65869" xyz="0 0 0" />
    <parent link="right_wrist_pitch" />
    <child link="right_wrist_roll" />
    <axis xyz="1 0 0" />
    <limit effort="1000" lower="-3.14" upper="3.14" velocity="100" />
  </joint>
  <!-- ~~~~~~~~~~~~~~~~~ right arm ~~~~~~~~~~~~~~~~~~~~~~~~~~~~~~~~ -->

  <!-- ~~~~~~~~~~~~~~~~~ left leg ~~~~~~~~~~~~~~~~~~~~~~~~~~~~~~~~ -->
  <link name="left_hip_pitch">
    <inertial>
      <origin rpy="0 0 0" xyz="-4.816e-05 -0.01075844 -0.05407776" />
      <mass value="1.6733645" />
      <inertia ixx="0.00234427" ixy="-2.8e-06" ixz="-8.23e-06" iyy="0.00252881" iyz="-0.00011548"
        izz="0.00218719" />
    </inertial>
    <visual>
      <origin rpy="0 0 0" xyz="0 0 0" />
      <geometry>
        <mesh filename="${mesh_path}/left_hip_pitch.STL" />
        <!-- <box size="0.10 0.10 0.10" /> -->
      </geometry>
      <material name="">
        <color rgba="1 1 1 1" />
      </material>
    </visual>
  </link>
  <joint name="left_hip_pitch_joint" type="revolute">
    <origin rpy="0 -0.7854 1.5708" xyz="0.00245 0.092277 -0.012143" />
    <parent link="base_link" />
    <child link="left_hip_pitch" />
    <axis xyz="0 0 1" />
    <limit effort="1000" lower="-3.14" upper="3.14" velocity="100" />
  </joint>
  <link name="left_hip_roll">
    <inertial>
      <origin rpy="0 0 0" xyz="0.00014604 -0.04123483 -0.01015339" />
      <mass value="0.28562185" />
      <inertia ixx="0.00055729" ixy="9.8e-07" ixz="5.6e-07" iyy="0.0004105" iyz="-0.00016545"
        izz="0.00047775" />
    </inertial>
    <visual>
      <origin rpy="0 0 0" xyz="0 0 0" />
      <geometry>
        <mesh filename="${mesh_path}/left_hip_roll.STL" />
        <!-- <box size="0.10 0.10 0.10" /> -->
      </geometry>
      <material name="">
        <color rgba="1 1 1 1" />
      </material>
    </visual>
  </link>
  <joint name="left_hip_roll_joint" type="revolute">
    <origin rpy="1.57079632679491 0.785398163397451 0"
      xyz="0 -0.0405000000000076 -0.0589000000000007" />
    <parent link="left_hip_pitch" />
    <child link="left_hip_roll" />
    <axis xyz="0 0 -1" />
    <limit effort="1000" lower="-3.14" upper="3.14" velocity="100" />
  </joint>
  <link name="left_hip_yaw">
    <inertial>
      <origin rpy="0 0 0" xyz="-0.00212295 -3.062e-05 0.09164842" />
      <mass value="2.7369623" />
      <inertia ixx="0.01270795" ixy="-2.44e-06" ixz="0.00060592" iyy="0.01244948" iyz="4.78e-06"
        izz="0.00342683" />
    </inertial>
    <visual>
      <origin rpy="0 0 0" xyz="0 0 0" />
      <geometry>
        <mesh filename="${mesh_path}/left_hip_yaw.STL" />
        <!-- <box size="0.10 0.10 0.10" /> -->
      </geometry>
      <material name="">
        <color rgba="1 1 1 1" />
      </material>
    </visual>
  </link>
  <joint name="left_hip_yaw_joint" type="revolute">
    <origin rpy="1.5707963267949 0 0" xyz="0 -0.0838049159474928 -0.0406000000000136" />
    <parent link="left_hip_roll" />
    <child link="left_hip_yaw" />
    <axis xyz="0 0 -1" />
    <limit effort="1000" lower="-3.14" upper="3.14" velocity="100" />
  </joint>
  <link name="left_knee_pitch">
    <inertial>
      <origin rpy="0 0 0" xyz="-0.0047354 -0.13101324 0.0279688" />
      <mass value="1.5122608" />
      <inertia ixx="0.00806663" ixy="-5.703e-05" ixz="3.669e-05" iyy="0.00174565" iyz="0.00090864"
        izz="0.00825577" />
    </inertial>
    <visual>
      <origin rpy="0 0 0" xyz="0 0 0" />
      <geometry>
        <mesh filename="${mesh_path}/left_knee_pitch.STL" />
        <!-- <box size="0.10 0.10 0.10" /> -->
      </geometry>
      <material name="">
        <color rgba="1 1 1 1" />
      </material>
    </visual>
  </link>
  <joint name="left_knee_pitch_joint" type="revolute">
    <origin rpy="-1.57079632679488 0 -1.5707963267949" xyz="-0.0337000000000097 0 0.142200000000001" />
    <parent link="left_hip_yaw" />
    <child link="left_knee_pitch" />
    <axis xyz="0 0 1" />
    <limit effort="1000" lower="-3.14" upper="3.14" velocity="100" />
  </joint>
  <link name="left_ankle_pitch">
    <inertial>
      <origin rpy="0 0 0" xyz="-2.32e-06 7.077e-05 -2.048e-05" />
      <mass value="0.06217211" />
      <inertia ixx="2.273e-05" ixy="0" ixz="0" iyy="2.373e-05" iyz="0" izz="6.68e-06" />
    </inertial>
    <visual>
      <origin rpy="0 0 0" xyz="0 0 0" />
      <geometry>
        <mesh filename="${mesh_path}/left_ankle_pitch.STL" />
        <!-- <box size="0.10 0.10 0.10" /> -->
      </geometry>
      <material name="">
        <color rgba="1 1 1 1" />
      </material>
    </visual>
  </link>
  <joint name="left_ankle_pitch_joint" type="revolute">
    <origin rpy="-3.14159265358979 0 3.14159265358979" xyz="0 -0.304939999999997 0.0336000000000411" />
    <parent link="left_knee_pitch" />
    <child link="left_ankle_pitch" />
    <axis xyz="0 0 -1" />
    <limit effort="1000" lower="-3.14" upper="3.14" velocity="100" />
  </joint>
  <link name="left_ankle_roll">
    <inertial>
      <origin rpy="0 0 0" xyz="0.00017156 -0.02524695 -0.00019936" />
      <mass value="0.58971207" />
      <inertia ixx="0.00152113" ixy="4.7e-07" ixz="3.91e-06" iyy="0.00189897" iyz="4.837e-05"
        izz="0.00054313" />
    </inertial>
    <visual>
      <origin rpy="0 0 0" xyz="0 0 0" />
      <geometry>
        <mesh filename="${mesh_path}/left_ankle_roll.STL" />
        <!-- <box size="0.10 0.10 0.10" /> -->
      </geometry>
      <material name="">
        <color rgba="1 1 1 1" />
      </material>
    </visual>
    <collision>
      <origin rpy="0 0 0" xyz="0 0 0" />
      <geometry>
        <mesh filename="${mesh_path}/left_ankle_roll.STL" />
      </geometry>
    </collision>
  </link>
  <joint name="left_ankle_roll_joint" type="revolute">
    <origin rpy="0 1.5707963267949 0" xyz="0 0 0" />
    <parent link="left_ankle_pitch" />
    <child link="left_ankle_roll" />
    <axis xyz="0 0 1" />
    <dynamics damping="0.2" friction="0.00" />
    <limit effort="1000" lower="-3.14" upper="3.14" velocity="100" />
  </joint>
  <link name="leg_l_toe_a_link">
    <inertial>
      <origin rpy="0 0 0" xyz="-0.00875902 0.00339112 -0.00875449" />
      <mass value="0.03114168" />
      <inertia ixx="4.33e-06" ixy="1.42e-06" ixz="-1.59e-06" iyy="7.48e-06" iyz="6.1e-07"
        izz="8.76e-06" />
    </inertial>
    <visual>
      <origin rpy="0 0 0" xyz="0 0 0" />
      <geometry>
        <mesh filename="${mesh_path}/leg_l_toe_a_link.STL" />
      </geometry>
      <material name="">
        <color rgba="1 1 1 1" />
      </material>
    </visual>
  </link>
  <joint name="leg_l_toe_a_link_joint" type="fixed">
    <origin rpy="0 -1.5707963267949 0"
      xyz="0.0198500000000011 -0.109961932116273 0.0336568378288508" />
    <parent link="left_knee_pitch" />
    <child link="leg_l_toe_a_link" />
    <axis xyz="0 0 -1" />
    <limit effort="1000" lower="-3.14" upper="3.14" velocity="100" />
  </joint>
  <link name="leg_l_toe_a_ball">
    <inertial>
      <origin rpy="0 0 0" xyz="-1.914e-5 -0.0941377 1.9e-6" />
      <mass value="0.05674707" />
      <inertia ixx="0.00022106" ixy="-1e-07" ixz="0" iyy="1.09e-06" iyz="-1e-08" izz="0.00022113" />
    </inertial>
    <visual>
      <origin rpy="0 0 0" xyz="0 0 0" />
      <geometry>
        <mesh filename="${mesh_path}/leg_l_toe_a_ball.STL" />
      </geometry>
      <material name="">
        <color rgba="1 1 1 1" />
      </material>
    </visual>

  </link>
  <joint name="leg_l_toe_a_ball_joint" type="fixed">
    <origin rpy="0 0 0" xyz="-0.0233806454082247 0.00902193211627456 -0.0211500000000038" />
    <parent link="leg_l_toe_a_link" />
    <child link="leg_l_toe_a_ball" />
    <axis xyz="0 0 0" />
  </joint>
  <link name="leg_l_toe_a_loop">
    <inertial>
      <origin rpy="0 0 0" xyz="0 0 -0.0006502" />
      <mass value="0.0062017" />
      <inertia ixx="2.8e-07" ixy="0" ixz="0" iyy="2.8e-07" iyz="0" izz="1.2e-07" />
    </inertial>
    <visual>
      <origin rpy="0 0 0" xyz="0 0 0" />
      <geometry>
        <mesh filename="${mesh_path}/leg_l_toe_a_loop.STL" />
      </geometry>
      <material name="">
        <color rgba="1 1 1 1" />
      </material>
    </visual>

  </link>
  <joint name="leg_l_toe_a_loop_joint" type="fixed">
    <origin rpy="0 1.5707963267949 0" xyz="0 -0.195 0" />
    <parent link="leg_l_toe_a_ball" />
    <child link="leg_l_toe_a_loop" />
    <axis xyz="0 0 0" />
  </joint>
  <link name="leg_l_toe_b_link">
    <inertial>
      <origin rpy="0 0 0" xyz="0.0089831 0.00345524 -0.00906395" />
      <mass value="0.03161" />
      <inertia ixx="4.6e-06" ixy="-1.46e-06" ixz="1.73e-06" iyy="7.81e-06" iyz="6.7e-07"
        izz="8.88e-06" />
    </inertial>
    <visual>
      <origin rpy="0 0 0" xyz="0 0 0" />
      <geometry>
        <mesh filename="${mesh_path}/leg_l_toe_b_link.STL" />
      </geometry>
      <material name="">
        <color rgba="1 1 1 1" />
      </material>
    </visual>

  </link>
  <joint name="leg_l_toe_b_link_joint" type="fixed">
    <origin rpy="0 -1.5707963267949 0"
      xyz="0.0198499999999967 -0.164961932116271 0.0335431621711256" />
    <parent link="left_knee_pitch" />
    <child link="leg_l_toe_b_link" />
    <axis xyz="0 0 -1" />
    <limit effort="1000" lower="-3.14" upper="3.14" velocity="100" />
  </joint>
  <link name="leg_l_toe_b_ball">
    <inertial>
      <origin rpy="0 0 0" xyz="-2.566e-5 -0.06676392 2.566e-5" />
      <mass value="0.0423305" />
      <inertia ixx="9.172e-05" ixy="-7e-08" ixz="0" iyy="9.5e-07" iyz="-7e-08" izz="9.179e-05" />
    </inertial>
    <visual>
      <origin rpy="0 0 0" xyz="0 0 0" />
      <geometry>
        <mesh filename="${mesh_path}/leg_l_toe_b_ball.STL" />
      </geometry>
      <material name="">
        <color rgba="1 1 1 1" />
      </material>
    </visual>

  </link>
  <joint name="leg_l_toe_b_ball_joint" type="fixed">
    <origin rpy="0 0 0" xyz="0.0233806454082588 0.00902193211627189 -0.0211500000000081" />
    <parent link="leg_l_toe_b_link" />
    <child link="leg_l_toe_b_ball" />
    <axis xyz="0 0 0" />
  </joint>
  <link name="leg_l_toe_b_loop">
    <inertial>
      <origin rpy="0 0 0" xyz="0 0 0.00064901" />
      <mass value="0.0062017" />
      <inertia ixx="2.8e-07" ixy="0" ixz="0" iyy="2.8e-07" iyz="0" izz="1.2e-07" />
    </inertial>
    <visual>
      <origin rpy="0 0 0" xyz="0 0 0" />
      <geometry>
        <mesh filename="${mesh_path}/leg_l_toe_b_loop.STL" />
      </geometry>
      <material name="">
        <color rgba="1 1 1 1" />
      </material>
    </visual>

  </link>
  <joint name="leg_l_toe_b_loop_joint" type="fixed">
    <origin rpy="0 1.5707963267949 0" xyz="0 -0.14 0" />
    <parent link="leg_l_toe_b_ball" />
    <child link="leg_l_toe_b_loop" />
    <axis xyz="0 0 0" />
  </joint>
  <!-- ~~~~~~~~~~~~~~~~~ left leg ~~~~~~~~~~~~~~~~~~~~~~~~~~~~~~~~ -->

  <!-- ~~~~~~~~~~~~~~~~~ right leg ~~~~~~~~~~~~~~~~~~~~~~~~~~~~~~~~ -->
  <link name="right_hip_pitch">
    <inertial>
      <origin rpy="0 0 0" xyz="-0.00011915 0.01061483 -0.05407727" />
      <mass value="1.6665735" />
      <inertia ixx="0.00232109" ixy="6.27e-06" ixz="-4.66e-06" iyy="0.00250972" iyz="0.00011538"
        izz="0.00216871" />
    </inertial>
    <visual>
      <origin rpy="0 0 0" xyz="0 0 0" />
      <geometry>
        <mesh filename="${mesh_path}/right_hip_pitch.STL" />
        <!-- <box size="0.10 0.10 0.10" /> -->
      </geometry>
      <material name="">
        <color rgba="1 1 1 1" />
      </material>
    </visual>
  </link>
  <joint name="right_hip_pitch_joint" type="revolute">
    <origin rpy="0 -0.7854 -1.5708" xyz="0.00245 -0.092277 -0.012143" />
    <parent link="base_link" />
    <child link="right_hip_pitch" />
    <axis xyz="0 0 1" />
    <limit effort="1000" lower="-3.14" upper="3.14" velocity="100" />
  </joint>
  <link name="right_hip_roll">
    <inertial>
      <origin rpy="0 0 0" xyz="-0.00027058 -0.04164617 0.01034263" />
      <mass value="0.28768793" />
      <inertia ixx="0.0005667" ixy="-5.75e-06" ixz="2.7e-06" iyy="0.00041717" iyz="0.00016914"
        izz="0.00048988" />
    </inertial>
    <visual>
      <origin rpy="0 0 0" xyz="0 0 0" />
      <geometry>
        <mesh filename="${mesh_path}/right_hip_roll.STL" />
        <!-- <box size="0.10 0.10 0.10" /> -->
      </geometry>
      <material name="">
        <color rgba="1 1 1 1" />
      </material>
    </visual>
  </link>
  <joint name="right_hip_roll_joint" type="revolute">
    <origin rpy="1.57079632679491 0.78539816339745 0" xyz="0 0.0405000000001067 -0.0588999999999981" />
    <parent link="right_hip_pitch" />
    <child link="right_hip_roll" />
    <axis xyz="0 0 1" />
    <limit effort="1000" lower="-3.14" upper="3.14" velocity="100" />
  </joint>
  <link name="right_hip_yaw">
    <inertial>
      <origin rpy="0 0 0" xyz="-0.00241642 1.672e-05 -0.09704704" />
      <mass value="2.6963535" />
      <inertia ixx="0.01254086" ixy="-9.4e-07" ixz="-0.00059613" iyy="0.01225062" iyz="-3.99e-06"
        izz="0.00336389" />
    </inertial>
    <visual>
      <origin rpy="0 0 0" xyz="0 0 0" />
      <geometry>
        <mesh filename="${mesh_path}/right_hip_yaw.STL" />
        <!-- <box size="0.10 0.10 0.10" /> -->
      </geometry>
      <material name="">
        <color rgba="1 1 1 1" />
      </material>
    </visual>
  </link>
  <joint name="right_hip_yaw_joint" type="revolute">
    <origin rpy="-1.57079632680723 0 0.00861027512635925"
      xyz="0 -0.0777549159474913 0.0405999999999983" />
    <parent link="right_hip_roll" />
    <child link="right_hip_yaw" />
    <axis xyz="-0 0 1" />
    <limit effort="1000" lower="-3.14" upper="3.14" velocity="100" />
  </joint>
  <link name="right_knee_pitch">
    <inertial>
      <origin rpy="0 0 0" xyz="0.00477062 -0.13172342 0.02793834" />
      <mass value="1.50954" />
      <inertia ixx="0.0080222" ixy="3.758e-05" ixz="-3.424e-05" iyy="0.00174185" iyz="0.00090582"
        izz="0.00821165" />
    </inertial>
    <visual>
      <origin rpy="0 0 0" xyz="0 0 0" />
      <geometry>
        <mesh filename="${mesh_path}/right_knee_pitch.STL" />
        <!-- <box size="0.10 0.10 0.10" /> -->
      </geometry>
      <material name="">
        <color rgba="1 1 1 1" />
      </material>
    </visual>
  </link>
  <joint name="right_knee_pitch_joint" type="revolute">
    <origin rpy="1.57940660192126 0 1.57079632822694" xyz="-0.0347752157308957 0 -0.147956063988164" />
    <parent link="right_hip_yaw" />
    <child link="right_knee_pitch" />
    <axis xyz="0 0 -1" />
    <limit effort="1000" lower="-3.14" upper="3.14" velocity="100" />
  </joint>
  <link name="right_ankle_pitch">
    <inertial>
      <origin rpy="0 0 0" xyz="2.47e-06 -7.076e-05 -1.763e-05" />
      <mass value="0.06217211" />
      <inertia ixx="2.273e-05" ixy="0" ixz="0" iyy="2.373e-05" iyz="-1e-08" izz="6.68e-06" />
    </inertial>
    <visual>
      <origin rpy="0 0 0" xyz="0 0 0" />
      <geometry>
        <mesh filename="${mesh_path}/right_ankle_pitch.STL" />
        <!-- <box size="0.10 0.10 0.10" /> -->
      </geometry>
      <material name="">
        <color rgba="1 1 1 1" />
      </material>
    </visual>
  </link>
  <joint name="right_ankle_pitch_joint" type="revolute">
    <origin rpy="3.14159265358979 0 0" xyz="0 -0.304939999999999 0.0335999999999944" />
    <parent link="right_knee_pitch" />
    <child link="right_ankle_pitch" />
    <axis xyz="0 0 1" />
    <limit effort="1000" lower="-3.14" upper="3.14" velocity="100" />
  </joint>
  <link name="right_ankle_roll">
    <inertial>
      <origin rpy="0 0 0" xyz="-2.32e-06 0.02507893 0.00010556" />
      <mass value="0.59182763" />
      <inertia ixx="0.00151845" ixy="1e-08" ixz="5e-08" iyy="0.00189242" iyz="-4.706e-05"
        izz="0.00054401" />
    </inertial>
    <visual>
      <origin rpy="0 0 0" xyz="0 0 0" />
      <geometry>
        <mesh filename="${mesh_path}/right_ankle_roll.STL" />
        <!-- <box size="0.10 0.10 0.10" /> -->
      </geometry>
      <material name="">
        <color rgba="1 1 1 1" />
      </material>
    </visual>
    <collision>
      <origin rpy="0 0 0" xyz="0 0 0" />
      <geometry>
        <mesh filename="${mesh_path}/right_ankle_roll.STL" />
      </geometry>
    </collision>
  </link>
  <joint name="right_ankle_roll_joint" type="revolute">
    <origin rpy="0 1.5707963267949 0" xyz="0 0 0" />
    <parent link="right_ankle_pitch" />
    <child link="right_ankle_roll" />
    <axis xyz="0 0 1" />
    <dynamics damping="0.2" friction="0.00" />
    <limit effort="1000" lower="-3.14" upper="3.14" velocity="100" />
  </joint>
  <link name="leg_r_toe_a_link">
    <inertial>
      <origin rpy="0 0 0" xyz="0.00876658 0.00337152 -0.00875449" />
      <mass value="0.03114168" />
      <inertia ixx="4.34e-06" ixy="-1.43e-06" ixz="1.59e-06" iyy="7.47e-06" iyz="6.2e-07"
        izz="8.76e-06" />
    </inertial>
    <visual>
      <origin rpy="0 0 0" xyz="0 0 0" />
      <geometry>
        <mesh filename="${mesh_path}/leg_r_toe_a_link.STL" />
      </geometry>
      <material name="">
        <color rgba="1 1 1 1" />
      </material>
    </visual>
  </link>
  <joint name="leg_r_toe_a_link_joint" type="fixed">
    <origin rpy="0 1.5707963267949 0"
      xyz="-0.0198500000000012 -0.109961932116264 0.0336568378288726" />
    <parent link="right_knee_pitch" />
    <child link="leg_r_toe_a_link" />
    <axis xyz="0 0 -1" />
    <limit effort="1000" lower="-3.14" upper="3.14" velocity="100" />
  </joint>
  <link name="leg_r_toe_a_ball">
    <inertial>
      <origin rpy="0 0 0" xyz="-1.914e-5 -0.0941377 1.914e-5" />
      <mass value="0.05674707" />
      <inertia ixx="0.00022106" ixy="-1e-07" ixz="0" iyy="1.09e-06" iyz="-1e-07" izz="0.00022113" />
    </inertial>
    <visual>
      <origin rpy="0 0 0" xyz="0 0 0" />
      <geometry>
        <mesh filename="${mesh_path}/leg_r_toe_a_ball.STL" />
      </geometry>
      <material name="">
        <color rgba="1 1 1 1" />
      </material>
    </visual>

  </link>
  <joint name="leg_r_toe_a_ball_joint" type="fixed">
    <origin rpy="0 0 0" xyz="0.0233806454082594 0.00902193211626567 -0.0211499999999971" />
    <parent link="leg_r_toe_a_link" />
    <child link="leg_r_toe_a_ball" />
    <axis xyz="0 0 0" />
  </joint>
  <link name="leg_r_toe_a_loop">
    <inertial>
      <origin rpy="0 0 0" xyz="0 0 0.00064901" />
      <mass value="0.0062017" />
      <inertia ixx="2.8e-07" ixy="0" ixz="0" iyy="2.8e-07" iyz="0" izz="1.2e-07" />
    </inertial>
    <visual>
      <origin rpy="0 0 0" xyz="0 0 0" />
      <geometry>
        <mesh filename="${mesh_path}/leg_r_toe_a_loop.STL" />
      </geometry>
      <material name="">
        <color rgba="1 1 1 1" />
      </material>
    </visual>

  </link>
  <joint name="leg_r_toe_a_loop_joint" type="fixed">
    <origin rpy="0 1.5707963267949 0" xyz="0 -0.195000000000005 0" />
    <parent link="leg_r_toe_a_ball" />
    <child link="leg_r_toe_a_loop" />
    <axis xyz="0 0 0" />
  </joint>
  <link name="leg_r_toe_b_link">
    <inertial>
      <origin rpy="0 0 0" xyz="-0.00897565 0.00347454 -0.00906395" />
      <mass value="0.03161" />
      <inertia ixx="4.59e-06" ixy="1.46e-06" ixz="-1.73e-06" iyy="7.82e-06" iyz="6.7e-07"
        izz="8.88e-06" />
    </inertial>
    <visual>
      <origin rpy="0 0 0" xyz="0 0 0" />
      <geometry>
        <mesh filename="${mesh_path}/leg_r_toe_b_link.STL" />
      </geometry>
      <material name="">
        <color rgba="1 1 1 1" />
      </material>
    </visual>

  </link>
  <joint name="leg_r_toe_b_link_joint" type="fixed">
    <origin rpy="0 1.5707963267949 0"
      xyz="-0.0198500000000051 -0.164961932116276 0.0335431621711194" />
    <parent link="right_knee_pitch" />
    <child link="leg_r_toe_b_link" />
    <axis xyz="0 0 -1" />
    <limit effort="1000" lower="-3.14" upper="3.14" velocity="100" />
  </joint>
  <link name="leg_r_toe_b_ball">
    <inertial>
      <origin rpy="0 0 0" xyz="-2.566e-5 -0.06676392 2.566e-5" />
      <mass value="0.0423305" />
      <inertia ixx="9.172e-05" ixy="-7e-08" ixz="0" iyy="9.5e-07" iyz="-7e-08" izz="9.179e-05" />
    </inertial>
    <visual>
      <origin rpy="0 0 0" xyz="0 0 0" />
      <geometry>
        <mesh filename="${mesh_path}/leg_r_toe_b_ball.STL" />
      </geometry>
      <material name="">
        <color rgba="1 1 1 1" />
      </material>
    </visual>

  </link>
  <joint name="leg_r_toe_b_ball_joint" type="fixed">
    <origin rpy="0 0 0" xyz="-0.0233806454082563 0.00902193211627755 -0.0211499999999931" />
    <parent link="leg_r_toe_b_link" />
    <child link="leg_r_toe_b_ball" />
    <axis xyz="0 0 0" />
  </joint>
  <link name="leg_r_toe_b_loop">
    <inertial>
      <origin rpy="0 0 0" xyz="0 0 -0.00064901" />
      <mass value="0.0062017" />
      <inertia ixx="2.8e-07" ixy="0" ixz="0" iyy="2.8e-07" iyz="0" izz="1.2e-07" />
    </inertial>
    <visual>
      <origin rpy="0 0 0" xyz="0 0 0" />
      <geometry>
        <mesh filename="${mesh_path}/leg_r_toe_b_loop.STL" />
      </geometry>
      <material name="">
        <color rgba="1 1 1 1" />
      </material>
    </visual>

  </link>
  <joint name="leg_r_toe_b_loop_joint" type="fixed">
    <origin rpy="0 1.5707963267949 0" xyz="0 -0.14 0" />
    <parent link="leg_r_toe_b_ball" />
    <child link="leg_r_toe_b_loop" />
    <axis xyz="0 0 0" />
  </joint>
  <!-- ~~~~~~~~~~~~~~~~~ right leg ~~~~~~~~~~~~~~~~~~~~~~~~~~~~~~~~ -->

  <link name="arm_r_wrist_a_ball">
    <inertial>
      <origin rpy="0 0 0" xyz="0.00076586 -0.01156825 4.912e-05" />
      <mass value="0.23598732" />
      <inertia ixx="7.634e-05" ixy="1.26e-06" ixz="-3e-08" iyy="2.519e-05" iyz="-1e-07"
        izz="7.977e-05" />
    </inertial>
    <visual>
      <origin rpy="0 0 0" xyz="0 0 0" />
      <geometry>
        <mesh filename="${mesh_path}/arm_r_wrist_a_ball.STL" />
      </geometry>
      <material name="">
        <color rgba="1 1 1 1" />
      </material>
    </visual>

  </link>
  <joint name="arm_r_wrist_a_ball_joint" type="fixed">
    <origin rpy="1.5708 0 0" xyz="-0.009 -0.02 -0.0199" />
    <parent link="right_elbow_yaw" />
    <child link="arm_r_wrist_a_ball" />
    <axis xyz="0 0 0" />
  </joint>
  <link name="arm_r_wrist_motor_a_link">
    <inertial>
      <origin rpy="0 0 0" xyz="0 0 0.00973737" />
      <mass value="0.00117982" />
      <inertia ixx="6e-08" ixy="0" ixz="0" iyy="8e-08" iyz="0" izz="2e-08" />
    </inertial>
    <visual>
      <origin rpy="0 0 0" xyz="0 0 0" />
      <geometry>
        <mesh filename="${mesh_path}/arm_r_wrist_motor_a_link.STL" />
      </geometry>
      <material name="">
        <color rgba="1 1 1 1" />
      </material>
    </visual>

  </link>
  <joint name="arm_r_wrist_motor_a_link_joint" type="fixed">
    <origin rpy="1.5708 0 0.028438" xyz="0.0027628 -0.097124 0" />
    <parent link="arm_r_wrist_a_ball" />
    <child link="arm_r_wrist_motor_a_link" />
    <axis xyz="0 0 1" />
    <limit effort="1000" lower="-3.14" upper="3.14" velocity="100" />
  </joint>
  <link name="arm_r_wrist_a_loop">
    <inertial>
      <origin rpy="0 0 0" xyz="0 0 -1.922e-05" />
      <mass value="0.00548041" />
      <inertia ixx="8e-08" ixy="0" ixz="0" iyy="8e-08" iyz="0" izz="7e-08" />
    </inertial>
    <visual>
      <origin rpy="0 0 0" xyz="0 0 0" />
      <geometry>
        <mesh filename="${mesh_path}/arm_r_wrist_a_loop.STL" />
      </geometry>
      <material name="">
        <color rgba="1 1 1 1" />
      </material>
    </visual>

  </link>
  <joint name="arm_r_wrist_a_loop_joint" type="fixed">
    <origin rpy="-1.5708 -0.028438 0" xyz="0 0 0.0132" />
    <parent link="arm_r_wrist_motor_a_link" />
    <child link="arm_r_wrist_a_loop" />
    <axis xyz="0 0 0" />
  </joint>
  <link name="arm_r_wrist_b_ball">
    <inertial>
      <origin rpy="0 0 0" xyz="0.00121967 0.04417257 0" />
      <mass value="0.03617567" />
      <inertia ixx="1.73e-05" ixy="-4.1e-07" ixz="0" iyy="4.69e-06" iyz="0" izz="1.731e-05" />
    </inertial>
    <visual>
      <origin rpy="0 0 0" xyz="0 0 0" />
      <geometry>
        <mesh filename="${mesh_path}/arm_r_wrist_b_ball.STL" />
      </geometry>
      <material name="">
        <color rgba="1 1 1 1" />
      </material>
    </visual>

  </link>
  <joint name="arm_r_wrist_b_ball_joint" type="fixed">
    <origin rpy="-1.5708 0 0" xyz="-0.009 0.02 -0.0199" />
    <parent link="right_elbow_yaw" />
    <child link="arm_r_wrist_b_ball" />
    <axis xyz="0 0 0" />
  </joint>
  <link name="arm_r_wrist_motor_b_link">
    <inertial>
      <origin rpy="0 0 0" xyz="0 0 0.00973737" />
      <mass value="0.00117982" />
      <inertia ixx="6e-08" ixy="0" ixz="0" iyy="8e-08" iyz="0" izz="2e-08" />
    </inertial>
    <visual>
      <origin rpy="0 0 0" xyz="0 0 0" />
      <geometry>
        <mesh filename="${mesh_path}/arm_r_wrist_motor_b_link.STL" />
      </geometry>
      <material name="">
        <color rgba="1 1 1 1" />
      </material>
    </visual>

  </link>
  <joint name="arm_r_wrist_motor_b_link_joint" type="fixed">
    <origin rpy="-1.5708 0 -0.028438" xyz="0.0027628 0.097124 0" />
    <parent link="arm_r_wrist_b_ball" />
    <child link="arm_r_wrist_motor_b_link" />
    <axis xyz="0 0 1" />
    <limit effort="1000" lower="-3.14" upper="3.14" velocity="100" />
  </joint>
  <link name="arm_r_wrist_b_loop">
    <inertial>
      <origin rpy="0 0 0" xyz="0 0 -1.922e-05" />
      <mass value="0.00548041" />
      <inertia ixx="8e-08" ixy="0" ixz="0" iyy="8e-08" iyz="0" izz="7e-08" />
    </inertial>
    <visual>
      <origin rpy="0 0 0" xyz="0 0 0" />
      <geometry>
        <mesh filename="${mesh_path}/arm_r_wrist_b_loop.STL" />
      </geometry>
      <material name="">
        <color rgba="1 1 1 1" />
      </material>
    </visual>

  </link>
  <joint name="arm_r_wrist_b_loop_joint" type="fixed">
    <origin rpy="1.5708 -0.028438 0" xyz="0 0 0.0132" />
    <parent link="arm_r_wrist_motor_b_link" />
    <child link="arm_r_wrist_b_loop" />
    <axis xyz="0 0 0" />
  </joint>
  <link name="arm_l_wrist_a_ball">
    <inertial>
      <origin rpy="0 0 0" xyz="0.00076586 -0.01156825 4.912e-05" />
      <mass value="0.23598732" />
      <inertia ixx="7.634e-05" ixy="1.26e-06" ixz="-3e-08" iyy="2.519e-05" iyz="-1e-07"
        izz="7.977e-05" />
    </inertial>
    <visual>
      <origin rpy="0 0 0" xyz="0 0 0" />
      <geometry>
        <mesh filename="${mesh_path}/arm_r_wrist_a_ball.STL" />
      </geometry>
      <material name="">
        <color rgba="1 1 1 1" />
      </material>
    </visual>

  </link>
  <joint name="arm_l_wrist_a_ball_joint" type="fixed">
    <origin rpy="1.5708 0 0" xyz="-0.009 -0.02 -0.0199" />
    <parent link="left_elbow_yaw" />
    <child link="arm_l_wrist_a_ball" />
    <axis xyz="0 0 0" />
  </joint>
  <link name="arm_l_wrist_motor_a_link">
    <inertial>
      <origin rpy="0 0 0" xyz="0 0 0.00973737" />
      <mass value="0.00117982" />
      <inertia ixx="6e-08" ixy="0" ixz="0" iyy="8e-08" iyz="0" izz="2e-08" />
    </inertial>
    <visual>
      <origin rpy="0 0 0" xyz="0 0 0" />
      <geometry>
        <mesh filename="${mesh_path}/arm_r_wrist_motor_a_link.STL" />
      </geometry>
      <material name="">
        <color rgba="1 1 1 1" />
      </material>
    </visual>

  </link>
  <joint name="arm_l_wrist_motor_a_link_joint" type="fixed">
    <origin rpy="1.5708 0 0.028438" xyz="0.0027628 -0.097124 0" />
    <parent link="arm_l_wrist_a_ball" />
    <child link="arm_l_wrist_motor_a_link" />
    <axis xyz="0 0 1" />
    <limit effort="1000" lower="-3.14" upper="3.14" velocity="100" />
  </joint>
  <link name="arm_l_wrist_a_loop">
    <inertial>
      <origin rpy="0 0 0" xyz="0 0 -1.922e-05" />
      <mass value="0.00548041" />
      <inertia ixx="8e-08" ixy="0" ixz="0" iyy="8e-08" iyz="0" izz="7e-08" />
    </inertial>
    <visual>
      <origin rpy="0 0 0" xyz="0 0 0" />
      <geometry>
        <mesh filename="${mesh_path}/arm_r_wrist_a_loop.STL" />
      </geometry>
      <material name="">
        <color rgba="1 1 1 1" />
      </material>
    </visual>

  </link>
  <joint name="arm_l_wrist_a_loop_joint" type="fixed">
    <origin rpy="-1.5708 -0.028438 0" xyz="0 0 0.0132" />
    <parent link="arm_l_wrist_motor_a_link" />
    <child link="arm_l_wrist_a_loop" />
    <axis xyz="0 0 0" />
  </joint>
  <link name="arm_l_wrist_b_ball">
    <inertial>
      <origin rpy="0 0 0" xyz="0.00121967 0.04417257 0" />
      <mass value="0.03617567" />
      <inertia ixx="1.73e-05" ixy="-4.1e-07" ixz="0" iyy="4.69e-06" iyz="0" izz="1.731e-05" />
    </inertial>
    <visual>
      <origin rpy="0 0 0" xyz="0 0 0" />
      <geometry>
        <mesh filename="${mesh_path}/arm_r_wrist_b_ball.STL" />
      </geometry>
      <material name="">
        <color rgba="1 1 1 1" />
      </material>
    </visual>

  </link>
  <joint name="arm_l_wrist_b_ball_joint" type="fixed">
    <origin rpy="-1.5708 0 0" xyz="-0.009 0.02 -0.0199" />
    <parent link="left_elbow_yaw" />
    <child link="arm_l_wrist_b_ball" />
    <axis xyz="0 0 0" />
  </joint>
  <link name="arm_l_wrist_motor_b_link">
    <inertial>
      <origin rpy="0 0 0" xyz="0.00076586 0.01156825 -4.912e-05" />
      <mass value="0.23598732" />
      <inertia ixx="7.634e-05" ixy="-1.26e-06" ixz="3e-08" iyy="2.519e-05" iyz="-1e-07"
        izz="7.977e-05" />
    </inertial>
    <visual>
      <origin rpy="0 0 0" xyz="0 0 0" />
      <geometry>
        <mesh filename="${mesh_path}/arm_r_wrist_motor_b_link.STL" />
      </geometry>
      <material name="">
        <color rgba="1 1 1 1" />
      </material>
    </visual>

  </link>
  <joint name="arm_l_wrist_motor_b_link_joint" type="fixed">
    <origin rpy="-1.5708 0 -0.028438" xyz="0.0027628 0.097124 0" />
    <parent link="arm_l_wrist_b_ball" />
    <child link="arm_l_wrist_motor_b_link" />
    <axis xyz="0 0 1" />
    <limit effort="1000" lower="-3.14" upper="3.14" velocity="100" />
  </joint>
  <link name="arm_l_wrist_b_loop">
    <inertial>
      <origin rpy="0 0 0" xyz="0 0 0.00973737" />
      <mass value="0.00117982" />
      <inertia ixx="6e-08" ixy="0" ixz="0" iyy="8e-08" iyz="0" izz="2e-08" />
    </inertial>
    <visual>
      <origin rpy="0 0 0" xyz="0 0 0" />
      <geometry>
        <mesh filename="${mesh_path}/arm_r_wrist_b_loop.STL" />
      </geometry>
      <material name="">
        <color rgba="1 1 1 1" />
      </material>
    </visual>

  </link>
  <joint name="arm_l_wrist_b_loop_joint" type="fixed">
    <origin rpy="1.5708 -0.028438 0" xyz="0 0 0.0132" />
    <parent link="arm_l_wrist_motor_b_link" />
    <child link="arm_l_wrist_b_loop" />
    <axis xyz="0 0 0" />
  </joint>
</xacro:macro>